<?xml version="1.0" ?>
<robot name="prius">
  <joint name="prius_hybrid__front_left_combined_joint" type="revolute">
    <parent link="prius_hybrid__chassis"/>
    <child link="prius_hybrid__front_left_combined_joint__revolute_dummy_link"/>
    <origin xyz="0.76 -1.41  0.33" rpy="-0.08726  0       0"/>
    <axis xyz="0 0 1"/>
    <limit lower="-0.8727" upper="0.8727" effort="0.0" velocity="0.0"/>
  </joint>
  <link name="prius_hybrid__front_left_combined_joint__revolute_dummy_link"/>
  <joint name="prius_hybrid__front_left_combined_joint__revolute_dummy_joint" type="revolute">
    <parent link="prius_hybrid__front_left_combined_joint__revolute_dummy_link"/>
    <child link="prius_hybrid__front_left_wheel"/>
    <axis xyz="1 0 0"/>
    <limit lower="0" upper="0" effort="0" velocity="0"/>
  </joint>
  <joint name="prius_hybrid__front_right_combined_joint" type="revolute">
    <parent link="prius_hybrid__chassis"/>
    <child link="prius_hybrid__front_right_combined_joint__revolute_dummy_link"/>
    <origin xyz="-0.76 -1.41  0.33" rpy="-0.08726  0       0"/>
    <axis xyz="0 0 1"/>
    <limit lower="-0.8727" upper="0.8727" effort="0.0" velocity="0.0"/>
  </joint>
  <link name="prius_hybrid__front_right_combined_joint__revolute_dummy_link"/>
  <joint name="prius_hybrid__front_right_combined_joint__revolute_dummy_joint" type="revolute">
    <parent link="prius_hybrid__front_right_combined_joint__revolute_dummy_link"/>
    <child link="prius_hybrid__front_right_wheel"/>
    <axis xyz="1 0 0"/>
    <limit lower="0" upper="0" effort="0" velocity="0"/>
  </joint>
  <joint name="prius_hybrid__rear_axle_joint" type="revolute">
    <parent link="prius_hybrid__chassis"/>
    <child link="prius_hybrid__rear_axle"/>
    <origin xyz="0   1.45 0.33" rpy="0 0 0"/>
    <axis xyz="0 1 0"/>
    <limit lower="-0.05089058524173028" upper="0.05089058524173028" effort="0.0" velocity="0.0"/>
  </joint>
  <joint name="prius_hybrid__rear_left_wheel_joint" type="fixed">
    <parent link="prius_hybrid__rear_axle"/>
    <child link="prius_hybrid__rear_left_wheel"/>
    <origin xyz="0.786 0    0" rpy="0 0 0"/>
    <axis xyz="1 0 0"/>
    <limit lower="0" upper="0" effort="0" velocity="0"/>
  </joint>
  <joint name="prius_hybrid__rear_right_wheel_joint" type="fixed">
    <parent link="prius_hybrid__rear_axle"/>
    <child link="prius_hybrid__rear_right_wheel"/>
    <origin xyz="-0.786  0     0" rpy="0 0 0"/>
    <axis xyz="1 0 0"/>
    <limit lower="0" upper="0" effort="0" velocity="0"/>
  </joint>
  <joint name="prius_hybrid__steering_joint" type="revolute">
    <parent link="prius_hybrid__chassis"/>
    <child link="prius_hybrid__steering_wheel"/>
    <origin xyz="0.35573 -0.62786  1.01824" rpy="-1.3021  0      0"/>
    <axis xyz="0.e+00 -8.e-05  1.e+00"/>
    <limit lower="-7.85" upper="7.85" effort="0.0" velocity="0.0"/>
  </joint>

  <link name="prius_hybrid__chassis">
    <inertial>
      <mass value="1326.0"/>
      <origin xyz="0    -0.266  0.48" rpy="0 0 0"/>
      <inertia ixx="2581.13354740" ixy="0.0" ixz="0.0" iyy="591.30846112" iyz="0.0" izz="2681.95008628"/>
    </inertial>

    <collision name="prius_hybrid__chassis">
      <origin xyz="0    0.05  0.655" rpy="0 0 0"/>
      <geometry>
        <box size="1.7526 2.1 0.95"/>
      </geometry>
    </collision>
    <collision name="prius_hybrid__front_bumper">
      <origin xyz="0      -2       0.48848" rpy="0 0 0"/>
      <geometry>
        <box size="1.337282 0.48 0.566691"/>
      </geometry>
    </collision>
    <collision name="prius_hybrid__hood">
      <origin xyz="0      -1.90084  0.7063" rpy="0.34124 0      0"/>
      <geometry>
        <box size="1.597968 0.493107 0.265468"/>
      </geometry>
    </collision>
    <collision name="prius_hybrid__windshield">
      <origin xyz="0      -0.8751   1.06226" rpy="0.33547 0      0"/>
      <geometry>
        <box size="1.168381 1.654253 0.272347"/>
      </geometry>
    </collision>
    <collision name="prius_hybrid__top_front">
      <origin xyz="0      0.16123 1.41604" rpy="0.13503 0      0"/>
      <geometry>
        <box size="1.279154 0.625988 0.171868"/>
      </geometry>
    </collision>
    <collision name="prius_hybrid__top_rear">
      <origin xyz="0      0.81769 1.39006" rpy="-0.06899  0       0"/>
      <geometry>
        <box size="1.285130 0.771189 0.226557"/>
      </geometry>
    </collision>
    <collision name="prius_hybrid__rear_window">
      <origin xyz="0      1.64053 1.20512" rpy="-0.26201  0       0"/>
      <geometry>
        <box size="1.267845 1.116344 0.244286"/>
      </geometry>
    </collision>
    <collision name="prius_hybrid__trunk">
      <origin xyz="0      1.63705 0.91818" rpy="0 0 0"/>
      <geometry>
        <box size="1.788064 1.138988 0.482746"/>
      </geometry>
    </collision>
    <collision name="prius_hybrid__back_bumper">
      <origin xyz="0      2.05445 0.60787" rpy="0 0 0"/>
      <geometry>
        <box size="1.781650 0.512093 0.581427"/>
      </geometry>
    </collision>

    <visual name="prius_hybrid__chassis_visual">
      <origin xyz="0   0   0.03" rpy="0 0 0"/>
      <geometry>
        <mesh filename="package://object_spawner/urdf/meshes/Hybrid.obj" scale="0.01 0.01 0.01"/>
      </geometry>
    </visual>
    <visual name="prius_hybrid__interior_visual">
      <origin xyz="0   0   0.03" rpy="0 0 0"/>
      <geometry>
        <mesh filename="package://object_spawner/urdf/meshes/Hybrid.obj" scale="0.01 0.01 0.01"/>
      </geometry>
    </visual>
    <visual name="prius_hybrid__windows_visual">
      <origin xyz="0   0   0.03" rpy="0 0 0"/>
      <geometry>
        <mesh filename="package://object_spawner/urdf/meshes/Hybrid.obj" scale="0.01 0.01 0.01"/>
      </geometry>
    </visual>
  </link>

  <!--ruote sterzanti anteriori-->
  <link name="prius_hybrid__steering_wheel">
    <inertial>
      <mass value="1.0"/>
      <origin xyz="0 0 0" rpy="0 0 0"/>
      <inertia ixx="0.14583300" ixy="0" ixz="0" iyy="0.14583300" iyz="0" izz="0.12500000"/>
    </inertial>

    <collision name="prius_hybrid__collision">
      <origin xyz="0.002 0    0" rpy="0 0 0"/>
      <geometry>
        <cylinder radius="0.178172" length="0.041845"/>
      </geometry>
    </collision>
    
    <visual name="prius_hybrid__visual">
      <origin xyz="0.002 0    0" rpy="1.3021 0     0"/>
      <geometry>
        <mesh filename="package://object_spawner/urdf/meshes/Hybrid.obj" scale="0.01 0.01 0.01"/>
      </geometry>
    </visual>
  </link>

  <link name="prius_hybrid__front_left_wheel">
    <inertial>
      <mass value="11"/>
      <origin xyz="0 0 0" rpy="0 0 0"/>
      <inertia ixx="0.58631238" ixy="0.0" ixz="0.0" iyy="0.33552910" iyz="0.0" izz="0.33552910"/>
    </inertial>
    <collision name="prius_hybrid__collision">
      <origin xyz="0 0 0" rpy="1.57079 1.48353 1.57079"/>
      <geometry>
        <sphere radius="0.31265"/>
      </geometry>
    </collision>
    <visual name="prius_hybrid__visual">
      <origin xyz="0.04 0   0" rpy="0.08726 0      0"/>
      <geometry>
        <mesh filename="package://object_spawner/urdf/meshes/Hybrid.obj" scale="0.01 0.01 0.01"/>
      </geometry>
    </visual>
  </link>

  <link name="prius_hybrid__front_right_wheel">
    <inertial>
      <mass value="11"/>
      <origin xyz="0 0 0" rpy="0 0 0"/>
      <inertia ixx="0.58631238" ixy="0.0" ixz="0.0" iyy="0.33552910" iyz="0.0" izz="0.33552910"/>
    </inertial>
    <collision name="prius_hybrid__collision">
      <origin xyz="0 0 0" rpy="1.57079 1.48353 1.57079"/>
      <geometry>
        <sphere radius="0.31265"/>
      </geometry>
    </collision>
    <visual name="prius_hybrid__visual">
      <origin xyz="-0.04  0    0" rpy="0.08726 0      0"/>
      <geometry>
        <mesh filename="package://object_spawner/urdf/meshes/Hybrid.obj" scale="0.01 0.01 0.01"/>
      </geometry>
    </visual>
  </link>



  <!--ruote di dietro-->
  <link name="prius_hybrid__rear_left_wheel">
    <inertial>
      <mass value="11"/>
      <origin xyz="0 0 0" rpy="0 0 0"/>
      <inertia ixx="0.58631238" ixy="0.0" ixz="0.0" iyy="0.33552910" iyz="0.0" izz="0.33552910"/>
    </inertial>
    <collision name="prius_hybrid__collision">
      <origin xyz="0 0 0" rpy="0      1.57079 0"/>
      <geometry>
        <sphere radius="0.31265"/>
      </geometry>
    </collision>
    <visual name="prius_hybrid__visual">
      <origin xyz="0.04 0   0" rpy="0 0 0"/>
      <geometry>
        <mesh filename="package://object_spawner/urdf/meshes/Hybrid.obj" scale="0.01 0.01 0.01"/>
      </geometry>
    </visual>
  </link>
  <link name="prius_hybrid__rear_right_wheel">
    <inertial>
      <mass value="11"/>
      <origin xyz="0 0 0" rpy="0 0 0"/>
      <inertia ixx="0.58631238" ixy="0.0" ixz="0.0" iyy="0.33552910" iyz="0.0" izz="0.33552910"/>
    </inertial>
    <collision name="prius_hybrid__collision">
      <origin xyz="0 0 0" rpy="0      1.57079 0"/>
      <geometry>
        <sphere radius="0.31265"/>
      </geometry>
    </collision>
    <visual name="prius_hybrid__visual">
      <origin xyz="-0.04  0    0" rpy="0 0 0"/>
      <geometry>
        <mesh filename="package://object_spawner/urdf/meshes/Hybrid.obj" scale="0.01 0.01 0.01"/>
      </geometry>
    </visual>
  </link>
  <link name="prius_hybrid__rear_axle">
    <inertial>
      <mass value="30.0"/>
      <origin xyz="0 0 0" rpy="0 0 0"/>
      <inertia ixx="0.08437499999999999" ixy="0.0" ixz="0.0" iyy="4.64581" iyz="0.0" izz="4.64581"/>
    </inertial>
    <visual name="prius_hybrid__visual">
      <origin xyz="0 0 0" rpy="0      1.57079 0"/>
      <geometry>
        <cylinder radius="0.075" length="1.357"/>
      </geometry>
    </visual>
  </link>
</robot>
