<?xml version="1.0" ?>
<sdf version='1.7'>
  <model name='steering_robot'>
    <link name='map'>
      <inertial>
        <pose>0 0.05241 0.011928 0 -0 0</pose>
        <mass>830</mass>
        <inertia>
          <ixx>687.053</ixx>
          <ixy>0</ixy>
          <ixz>0</ixz>
          <iyy>149.021</iyy>
          <iyz>-13.8361</iyz>
          <izz>783.643</izz>
        </inertia>
      </inertial>
      <collision name='map_fixed_joint_lump__ferrari_chassis_collision'>
        <pose>0 0 0.7 0 -0 0</pose>
        <geometry>
          <box>
            <size>1.357 3 0.5</size>
          </box>
        </geometry>
        <surface>
          <contact>
            <ode/>
          </contact>
          <friction>
            <ode/>
          </friction>
        </surface>
      </collision>
      <collision name='map_fixed_joint_lump__ferrari_chassis_collision_1'>
        <pose>0 0 1.2 0 -0 0</pose>
        <geometry>
          <box>
            <size>1.357 1.5 0.5</size>
          </box>
        </geometry>
        <surface>
          <contact>
            <ode/>
          </contact>
          <friction>
            <ode/>
          </friction>
        </surface>
      </collision>
      <collision name='map_fixed_joint_lump__camera_link_collision_2'>
        <pose>0.972286 0.065 0.907 0 -0 0</pose>
        <geometry>
          <box>
            <size>0.012 0.132 0.02</size>
          </box>
        </geometry>
      </collision>
      <collision name='map_fixed_joint_lump__rear_axle_collision_3'>
        <pose>0 1.45 0.33 0 1.5708 0</pose>
        <geometry>
          <cylinder>
            <length>1.6</length>
            <radius>0.075</radius>
          </cylinder>
        </geometry>
      </collision>
      <visual name='map_fixed_joint_lump__ferrari_chassis_visual'>
        <pose>0 0 0.7 0 -0 0</pose>
        <geometry>
          <box>
            <size>1.357 3 0.5</size>
          </box>
        </geometry>
        <material>
          <script>
            <name>Gazebo/Red</name>
            <uri>file://media/materials/scripts/gazebo.material</uri>
          </script>
        </material>
      </visual>
      <visual name='map_fixed_joint_lump__ferrari_chassis_visual_1'>
        <pose>0 0 1.2 0 -0 0</pose>
        <geometry>
          <box>
            <size>1.357 1 0.5</size>
          </box>
        </geometry>
        <material>
          <script>
            <name>Gazebo/Red</name>
            <uri>file://media/materials/scripts/gazebo.material</uri>
          </script>
        </material>
      </visual>
      <visual name='map_fixed_joint_lump__ferrari_chassis_visual_2'>
        <pose>0 0 0.7 0 -0 0</pose>
        <geometry>
          <box>
            <size>1.557 2 0.5</size>
          </box>
        </geometry>
        <material>
          <script>
            <name>Gazebo/Red</name>
            <uri>file://media/materials/scripts/gazebo.material</uri>
          </script>
        </material>
      </visual>
      <visual name='map_fixed_joint_lump__ferrari_chassis_visual_3'>
        <pose>0 0 0.7 0 -0 0</pose>
        <geometry>
          <box>
            <size>1.757 1.5 0.5</size>
          </box>
        </geometry>
        <material>
          <script>
            <name>Gazebo/Red</name>
            <uri>file://media/materials/scripts/gazebo.material</uri>
          </script>
        </material>
      </visual>
      <visual name='map_fixed_joint_lump__ferrari_chassis_visual_4'>
        <pose>0.5 1.4 1.05 0 -0 0</pose>
        <geometry>
          <box>
            <size>0.1 0.1 0.3</size>
          </box>
        </geometry>
        <material>
          <script>
            <name>Gazebo/Red</name>
            <uri>file://media/materials/scripts/gazebo.material</uri>
          </script>
        </material>
      </visual>
      <visual name='map_fixed_joint_lump__ferrari_chassis_visual_5'>
        <pose>-0.5 1.4 1.05 0 -0 0</pose>
        <geometry>
          <box>
            <size>0.1 0.1 0.3</size>
          </box>
        </geometry>
        <material>
          <script>
            <name>Gazebo/Red</name>
            <uri>file://media/materials/scripts/gazebo.material</uri>
          </script>
        </material>
      </visual>
      <visual name='map_fixed_joint_lump__ferrari_chassis_visual_6'>
        <pose>0 1.4 1.25 0 -0 0</pose>
        <geometry>
          <box>
            <size>1.357 0.2 0.1</size>
          </box>
        </geometry>
        <material>
          <script>
            <name>Gazebo/Red</name>
            <uri>file://media/materials/scripts/gazebo.material</uri>
          </script>
        </material>
      </visual>
      <visual name='map_fixed_joint_lump__ferrari_chassis_visual_7'>
        <pose>0 -1 1.05 0.6 -0 0</pose>
        <geometry>
          <box>
            <size>1.357 1.357 0.1</size>
          </box>
        </geometry>
        <material>
          <script>
            <name>Gazebo/Red</name>
            <uri>file://media/materials/scripts/gazebo.material</uri>
          </script>
        </material>
      </visual>
      <visual name='map_fixed_joint_lump__ferrari_chassis_visual_8'>
        <pose>0 0.75 1.05 -0.8 0 0</pose>
        <geometry>
          <box>
            <size>1.357 0.8785 0.1</size>
          </box>
        </geometry>
        <material>
          <script>
            <name>Gazebo/Red</name>
            <uri>file://media/materials/scripts/gazebo.material</uri>
          </script>
        </material>
      </visual>
      <visual name='map_fixed_joint_lump__camera_link_visual_9'>
        <pose>0.969286 0 0.9 1.57 -0 1.57</pose>
        <geometry>
          <mesh>
            <scale>1 1 1</scale>
            <uri>model://autopark/urdf/meshes/sensors/r200.dae</uri>
          </mesh>
        </geometry>
      </visual>
      <visual name='map_fixed_joint_lump__hokuyo_link_visual_10'>
        <pose>0.969286 0 0.7 0 -0 3.14</pose>
        <geometry>
          <box>
            <size>0.05 0.05 0.05</size>
          </box>
        </geometry>
        <material>
          <script>
            <name>Gazebo/Blue</name>
            <uri>file://media/materials/scripts/gazebo.material</uri>
          </script>
        </material>
      </visual>
      <visual name='map_fixed_joint_lump__rear_axle_visual_11'>
        <pose>0 1.45 0.33 0 1.5708 0</pose>
        <geometry>
          <cylinder>
            <length>1.6</length>
            <radius>0.075</radius>
          </cylinder>
        </geometry>
      </visual>
      <velocity_decay/>
      <velocity_decay/>
      <sensor name='camera1' type='depth'>
        <always_on>1</always_on>
        <visualize>0</visualize>
        <camera>
          <horizontal_fov>1.3439</horizontal_fov>
          <image>
            <width>1920</width>
            <height>1080</height>
            <format>R8G8B8</format>
          </image>
          <depth_camera>
            <output>depths</output>
          </depth_camera>
          <clip>
            <near>0.03</near>
            <far>100</far>
          </clip>
        </camera>
        <plugin name='camera_controller' filename='libgazebo_ros_openni_kinect.so'>
          <baseline>0.2</baseline>
          <alwaysOn>1</alwaysOn>
          <updateRate>30.0</updateRate>
          <cameraName>camera</cameraName>
          <frameName>camera_rgb_optical_frame</frameName>
          <imageTopicName>rgb/image_raw</imageTopicName>
          <depthImageTopicName>depth/image_raw</depthImageTopicName>
          <pointCloudTopicName>depth/points</pointCloudTopicName>
          <cameraInfoTopicName>rgb/camera_info</cameraInfoTopicName>
          <depthImageCameraInfoTopicName>depth/camera_info</depthImageCameraInfoTopicName>
          <pointCloudCutoff>0.4</pointCloudCutoff>
          <hackBaseline>0.07</hackBaseline>
          <distortionK1>0.0</distortionK1>
          <distortionK2>0.0</distortionK2>
          <distortionK3>0.0</distortionK3>
          <distortionT1>0.0</distortionT1>
          <distortionT2>0.0</distortionT2>
          <CxPrime>0.0</CxPrime>
          <Cx>0.0</Cx>
          <Cy>0.0</Cy>
          <focalLength>0</focalLength>
          <hackBaseline>0</hackBaseline>
        </plugin>
        <pose>0.974286 0.018 0.913 0 -0 0</pose>
      </sensor>
      <gravity>1</gravity>
      <velocity_decay/>
      <sensor name='head_hokuyo_sensor' type='ray'>
        <visualize>1</visualize>
        <update_rate>40</update_rate>
        <ray>
          <scan>
            <horizontal>
              <samples>720</samples>
              <resolution>1</resolution>
              <min_angle>-1.5708</min_angle>
              <max_angle>1.5708</max_angle>
            </horizontal>
          </scan>
          <range>
            <min>0.1</min>
            <max>8</max>
            <resolution>0.001</resolution>
          </range>
        </ray>
        <plugin name='gazebo_ros_head_hokuyo_controller' filename='libgazebo_ros_laser.so'>
          <topicName>/scan</topicName>
          <frameName>hokuyo_link</frameName>
        </plugin>
        <pose>0.969286 0 0.7 0 -0 0</pose>
      </sensor>
    </link>
    <joint name='front_left_steering_joint' type='revolute'>
      <pose relative_to='map'>0.8 -1.4 0.33 0 -0 0</pose>
      <parent>map</parent>
      <child>front_left_steering</child>
      <axis>
        <xyz>0 0 1</xyz>
        <limit>
          <lower>-0.6</lower>
          <upper>0.6</upper>
          <effort>10000</effort>
          <velocity>1000</velocity>
        </limit>
        <dynamics>
          <spring_reference>0</spring_reference>
          <spring_stiffness>0</spring_stiffness>
        </dynamics>
      </axis>
      <physics>
        <ode>
          <limit>
            <cfm>0</cfm>
            <erp>0.2</erp>
          </limit>
        </ode>
      </physics>
    </joint>
    <link name='front_left_steering'>
      <pose relative_to='front_left_steering_joint'>0 0 0 0 -0 0</pose>
      <inertial>
        <pose>0 0 0 0 -0 0</pose>
        <mass>50</mass>
        <inertia>
          <ixx>0.416667</ixx>
          <ixy>0</ixy>
          <ixz>0</ixz>
          <iyy>0.0833333</iyy>
          <iyz>0</iyz>
          <izz>0.416667</izz>
        </inertia>
      </inertial>
      <collision name='front_left_steering_collision'>
        <pose>0 0 0 0 -0 0</pose>
        <geometry>
          <box>
            <size>0.1 0.3 0.1</size>
          </box>
        </geometry>
      </collision>
      <visual name='front_left_steering_visual'>
        <pose>0 0 0 0 -0 0</pose>
        <geometry>
          <box>
            <size>0.1 0.3 0.1</size>
          </box>
        </geometry>
      </visual>
    </link>
    <joint name='front_right_steering_wheel_joint' type='revolute'>
      <pose relative_to='front_left_steering'>0.3 0 0 0 -0 0</pose>
      <parent>front_left_steering</parent>
      <child>front_right_steering_wheel</child>
      <axis>
        <xyz>1 0 0</xyz>
        <limit>
          <lower>-1e+16</lower>
          <upper>1e+16</upper>
        </limit>
        <dynamics>
          <damping>0.01</damping>
          <friction>0</friction>
          <spring_reference>0</spring_reference>
          <spring_stiffness>0</spring_stiffness>
        </dynamics>
      </axis>
      <physics>
        <ode>
          <limit>
            <cfm>0</cfm>
            <erp>0.2</erp>
          </limit>
        </ode>
      </physics>
    </joint>
    <link name='front_right_steering_wheel'>
      <pose relative_to='front_right_steering_wheel_joint'>0 0 0 0 -0 0</pose>
      <inertial>
        <pose>0 0 0 0 -0 0</pose>
        <mass>30</mass>
        <inertia>
          <ixx>0.91675</ixx>
          <ixy>0</ixy>
          <ixz>0</ixz>
          <iyy>0.91675</iyy>
          <iyz>0</iyz>
          <izz>1.6335</izz>
        </inertia>
      </inertial>
      <collision name='front_right_steering_wheel_collision'>
        <pose>0 0 0 0 1.5708 0</pose>
        <geometry>
          <cylinder>
            <length>0.2</length>
            <radius>0.33</radius>
          </cylinder>
        </geometry>
        <surface>
          <contact>
            <ode/>
          </contact>
          <friction>
            <ode/>
          </friction>
        </surface>
      </collision>
      <visual name='front_right_steering_wheel_visual'>
        <pose>0 0 0 0 -0 0</pose>
        <geometry>
          <mesh>
            <scale>0.01 0.01 0.01</scale>
            <uri>model://autopark/urdf/meshes/wheel.dae</uri>
          </mesh>
        </geometry>
        <material>
          <script>
            <name>Gazebo/Black</name>
            <uri>file://media/materials/scripts/gazebo.material</uri>
          </script>
        </material>
      </visual>
      <gravity>1</gravity>
      <velocity_decay/>
    </link>
    <joint name='front_right_steering_joint' type='revolute'>
      <pose relative_to='map'>-0.8 -1.4 0.33 0 -0 0</pose>
      <parent>map</parent>
      <child>front_right_steering</child>
      <axis>
        <xyz>0 0 1</xyz>
        <limit>
          <lower>-0.6</lower>
          <upper>0.6</upper>
          <effort>10000</effort>
          <velocity>1000</velocity>
        </limit>
        <dynamics>
          <spring_reference>0</spring_reference>
          <spring_stiffness>0</spring_stiffness>
        </dynamics>
      </axis>
      <physics>
        <ode>
          <limit>
            <cfm>0</cfm>
            <erp>0.2</erp>
          </limit>
        </ode>
      </physics>
    </joint>
    <link name='front_right_steering'>
      <pose relative_to='front_right_steering_joint'>0 0 0 0 -0 0</pose>
      <inertial>
        <pose>0 0 0 0 -0 0</pose>
        <mass>50</mass>
        <inertia>
          <ixx>0.416667</ixx>
          <ixy>0</ixy>
          <ixz>0</ixz>
          <iyy>0.0833333</iyy>
          <iyz>0</iyz>
          <izz>0.416667</izz>
        </inertia>
      </inertial>
      <collision name='front_right_steering_collision'>
        <pose>0 0 0 0 -0 0</pose>
        <geometry>
          <box>
            <size>0.1 0.3 0.1</size>
          </box>
        </geometry>
      </collision>
      <visual name='front_right_steering_visual'>
        <pose>0 0 0 0 -0 0</pose>
        <geometry>
          <box>
            <size>0.1 0.3 0.1</size>
          </box>
        </geometry>
      </visual>
    </link>
    <joint name='front_left_steering_wheel_joint' type='revolute'>
      <pose relative_to='front_right_steering'>-0.3 0 0 0 -0 0</pose>
      <parent>front_right_steering</parent>
      <child>front_left_steering_wheel</child>
      <axis>
        <xyz>1 0 0</xyz>
        <limit>
          <lower>-1e+16</lower>
          <upper>1e+16</upper>
        </limit>
        <dynamics>
          <damping>0.01</damping>
          <friction>0</friction>
          <spring_reference>0</spring_reference>
          <spring_stiffness>0</spring_stiffness>
        </dynamics>
      </axis>
      <physics>
        <ode>
          <limit>
            <cfm>0</cfm>
            <erp>0.2</erp>
          </limit>
        </ode>
      </physics>
    </joint>
    <link name='front_left_steering_wheel'>
      <pose relative_to='front_left_steering_wheel_joint'>0 0 0 0 -0 0</pose>
      <inertial>
        <pose>0 0 0 0 -0 0</pose>
        <mass>30</mass>
        <inertia>
          <ixx>0.91675</ixx>
          <ixy>0</ixy>
          <ixz>0</ixz>
          <iyy>0.91675</iyy>
          <iyz>0</iyz>
          <izz>1.6335</izz>
        </inertia>
      </inertial>
      <collision name='front_left_steering_wheel_collision'>
        <pose>0 0 0 0 1.5708 0</pose>
        <geometry>
          <cylinder>
            <length>0.2</length>
            <radius>0.33</radius>
          </cylinder>
        </geometry>
        <surface>
          <contact>
            <ode/>
          </contact>
          <friction>
            <ode/>
          </friction>
        </surface>
      </collision>
      <visual name='front_left_steering_wheel_visual'>
        <pose>0 0 0 0 -0 0</pose>
        <geometry>
          <mesh>
            <scale>0.01 0.01 0.01</scale>
            <uri>model://autopark/urdf/meshes/wheel.dae</uri>
          </mesh>
        </geometry>
        <material>
          <script>
            <name>Gazebo/Black</name>
            <uri>file://media/materials/scripts/gazebo.material</uri>
          </script>
        </material>
      </visual>
      <gravity>1</gravity>
      <velocity_decay/>
    </link>
    <joint name='rear_left_wheel_joint' type='revolute'>
      <pose relative_to='map'>0.8 1.45 0.33 0 -0 0</pose>
      <parent>map</parent>
      <child>rear_left_wheel</child>
      <axis>
        <xyz>1 0 0</xyz>
        <limit>
          <lower>-1e+16</lower>
          <upper>1e+16</upper>
        </limit>
        <dynamics>
          <damping>0.01</damping>
          <friction>0</friction>
          <spring_reference>0</spring_reference>
          <spring_stiffness>0</spring_stiffness>
        </dynamics>
      </axis>
      <physics>
        <ode>
          <limit>
            <cfm>0</cfm>
            <erp>0.2</erp>
          </limit>
        </ode>
      </physics>
    </joint>
    <link name='rear_left_wheel'>
      <pose relative_to='rear_left_wheel_joint'>0 0 0 0 -0 0</pose>
      <inertial>
        <pose>0 0 0 0 -0 0</pose>
        <mass>30</mass>
        <inertia>
          <ixx>0.91675</ixx>
          <ixy>0</ixy>
          <ixz>0</ixz>
          <iyy>0.91675</iyy>
          <iyz>0</iyz>
          <izz>1.6335</izz>
        </inertia>
      </inertial>
      <collision name='rear_left_wheel_collision'>
        <pose>0 0 0 0 1.5708 0</pose>
        <geometry>
          <cylinder>
            <length>0.2</length>
            <radius>0.33</radius>
          </cylinder>
        </geometry>
        <surface>
          <contact>
            <ode/>
          </contact>
          <friction>
            <ode/>
          </friction>
        </surface>
      </collision>
      <visual name='rear_left_wheel_visual'>
        <pose>0 0 0 0 -0 0</pose>
        <geometry>
          <mesh>
            <scale>0.01 0.01 0.01</scale>
            <uri>model://autopark/urdf/meshes/wheel.dae</uri>
          </mesh>
        </geometry>
        <material>
          <script>
            <name>Gazebo/Black</name>
            <uri>file://media/materials/scripts/gazebo.material</uri>
          </script>
        </material>
      </visual>
      <gravity>1</gravity>
      <velocity_decay/>
    </link>
    <joint name='rear_right_wheel_joint' type='revolute'>
      <pose relative_to='map'>-0.8 1.45 0.33 0 -0 0</pose>
      <parent>map</parent>
      <child>rear_right_wheel</child>
      <axis>
        <xyz>1 0 0</xyz>
        <limit>
          <lower>-1e+16</lower>
          <upper>1e+16</upper>
        </limit>
        <dynamics>
          <damping>0.01</damping>
          <friction>0</friction>
          <spring_reference>0</spring_reference>
          <spring_stiffness>0</spring_stiffness>
        </dynamics>
      </axis>
      <physics>
        <ode>
          <limit>
            <cfm>0</cfm>
            <erp>0.2</erp>
          </limit>
        </ode>
      </physics>
    </joint>
    <link name='rear_right_wheel'>
      <pose relative_to='rear_right_wheel_joint'>0 0 0 0 -0 0</pose>
      <inertial>
        <pose>0 0 0 0 -0 0</pose>
        <mass>30</mass>
        <inertia>
          <ixx>0.91675</ixx>
          <ixy>0</ixy>
          <ixz>0</ixz>
          <iyy>0.91675</iyy>
          <iyz>0</iyz>
          <izz>1.6335</izz>
        </inertia>
      </inertial>
      <collision name='rear_right_wheel_collision'>
        <pose>0 0 0 0 1.5708 0</pose>
        <geometry>
          <cylinder>
            <length>0.2</length>
            <radius>0.33</radius>
          </cylinder>
        </geometry>
        <surface>
          <contact>
            <ode/>
          </contact>
          <friction>
            <ode/>
          </friction>
        </surface>
      </collision>
      <visual name='rear_right_wheel_visual'>
        <pose>0 0 0 0 -0 0</pose>
        <geometry>
          <mesh>
            <scale>0.01 0.01 0.01</scale>
            <uri>model://autopark/urdf/meshes/wheel.dae</uri>
          </mesh>
        </geometry>
        <material>
          <script>
            <name>Gazebo/Black</name>
            <uri>file://media/materials/scripts/gazebo.material</uri>
          </script>
        </material>
      </visual>
      <gravity>1</gravity>
      <velocity_decay/>
    </link>
    <plugin name='gazebo_ros_control' filename='libgazebo_ros_control.so'>
      <robotNamespace>/steering_robot</robotNamespace>
      <robotSimType>gazebo_ros_control/DefaultRobotHWSim</robotSimType>
      <legacyModeNS>1</legacyModeNS>
    </plugin>
    <plugin name='joint_state_publisher' filename='libgazebo_ros_joint_state_publisher.so'>
      <jointName>rear_right_wheel_joint, rear_left_wheel_joint, front_right_steering_joint, front_left_steering_joint, front_right_steering_wheel_joint, front_left_steering_wheel_joint</jointName>
      <updateRate>50.0</updateRate>
      <robotNamespace>/steering_robot</robotNamespace>
      <alwaysOn>1</alwaysOn>
    </plugin>
    <plugin name='cmdvel_controller' filename='libcatvehiclegazebo.so'>
      <robotNamespace>/steering_robot</robotNamespace>
    </plugin>
    <plugin name='gazebo_ros_control' filename='libgazebo_ros_control.so'/>
    <static>0</static>
    <plugin name='robot_groundtruth_sim' filename='libgazebo_ros_p3d.so'>
      <alwaysOn>1</alwaysOn>
      <updateRate>100.0</updateRate>
      <topicName>ground_truth/state</topicName>
      <gaussianNoise>0.0</gaussianNoise>
      <frameName>map</frameName>
      <xyzOffsets>0 0 0</xyzOffsets>
      <rpyOffsets>0 0 0</rpyOffsets>
      <bodyName>map</bodyName>
      <xyzOffset>0 0 0</xyzOffset>
      <rpyOffset>0 -0 0</rpyOffset>
    </plugin>
  </model>
</sdf>
